---
title: "finally in subtask called from block"
date: 2020-10-07T00:11:33+1010:00
draft: false
weight: 1940

---

##### Showcases that you can use finally block to do clean up in more complex sub task level using code block


### Demo








[source](https://github.com/upcmd/up/blob/master/tests/functests/c0184.yml)

##### Main task yaml file
```
    tasks:
    - name: task
      task:
      - func: block
        desc: task
        do:
        - func: call
          do: sub_task_layer1
    - name: sub_task_layer1
      desc: sub_task_layer1
      task:
      - func: call
        loop:
        - item1
        - item2
        do:
        - sub_task_layer2
    - name: sub_task_layer2
      task:
      - func: shell
        name: step1
        desc: step 1
        do:
        - 'echo """opening file: {{.loopitem}}"""'
        - echo "hello"|grep "world"
        flags: [ignoreError]
      - func: cmd
        name: step2
        desc: |
          in this case, since there is no ignoreError, the exception was captured by task level finaly code block
          opened file is safely closed
          to make the flow to continue to reach step2, use ignoreError
        do:
        - name: print
          cmd: step 2
      desc: |
        without rescue, the execution will return a non-zero  return code in shell and also report the error
        with rescue, the program will return 0
      rescue: true
      finally:
      - func: shell
        name: close_file
        desc: |
          ensure the opened file is closed
        do:
        - echo "close the file ....."
    
```
##### Main log file
```
    loading [Config]:  ./tests/functests/upconfig.yml
    Main config:
                 Version -> 1.0.0
                  RefDir -> ./tests/functests
                 WorkDir -> cwd
              AbsWorkDir -> /up_project/up
                TaskFile -> c0184
                 Verbose -> vvv
              ModuleName -> self
               ShellType -> /bin/sh
           MaxCallLayers -> 8
                 Timeout -> 3600000
     MaxModuelCallLayers -> 256
               EntryTask -> task
      ModRepoUsernameRef -> 
      ModRepoPasswordRef -> 
    work dir: /up_project/up
    -exec task: task
    loading [Task]:  ./tests/functests/c0184
    module: [self], instance id: [dev], exec profile: []
    profile -  envVars:
    
    (*core.Cache)({
    })
    
    Task1: [task ==> task:  ]
    -Step1: [: task ]
    self: final context exec vars:
    
    (*core.Cache)({
      "up_runtime_task_layer_number": 0
    })
    
    -Step1:
    self: final context exec vars:
    
    (*core.Cache)({
      "up_runtime_task_layer_number": 0
    })
    
    =Task2: [task ==> sub_task_layer1: sub_task_layer1 ]
    --Step1:
    self: final context exec vars:
    
    (*core.Cache)({
      "up_runtime_task_layer_number": 1
    })
    
    ==Task3: [task/sub_task_layer1 ==> sub_task_layer2: without rescue, the execution will return a non-zero  return code in shell and also report the error
    with rescue, the program will return 0
     ]
    ---Step1: [step1: step 1 ]
    self: final context exec vars:
    
    (*core.Cache)({
      "loopindex1": 1,
      "up_runtime_task_layer_number": 2,
      "loopitem": "item1",
      "loopindex": 0
    })
    
    cmd( 1):
    echo """opening file: {{.loopitem}}"""
    
    -
    opening file: item1
    
    -
     .. ok
    cmd( 2):
    echo "hello"|grep "world"
    
    -
    
    -
     .. failed(suppressed if it is not the last step)
     WARN: [ignoreError:] - [Error ignored!!!]
    ---Step2: [
    step2in this case, since there is no ignoreError, the exception was captured by task level finaly code block
    opened file is safely closed
    to make the flow to continue to reach step2, use ignoreError
    ]
    self: final context exec vars:
    
    (*core.Cache)({
      "up_runtime_task_layer_number": 2,
      "loopitem": "item1",
      "loopindex": 0,
      "loopindex1": 1,
      "last_result": (*utils.ExecResult)({
        Cmd: "echo \"hello\"|grep \"world\"",
        Code: 1,
        Output: "",
        ErrMsg: "exit status 1"
      })
    })
    
    ~~~SubStep1: [print:  ]
    step 2
    task Finally:
    --Step1: [
    close_fileensure the opened file is closed
    ]
    self: final context exec vars:
    
    (*core.Cache)({
      "up_runtime_task_layer_number": 2,
      "loopitem": "item1",
      "loopindex": 0,
      "loopindex1": 1
    })
    
    cmd( 1):
    echo "close the file ....."
    
    -
    close the file .....
    
    -
     .. ok
    . ok
    ==Task3: [task/sub_task_layer1 ==> sub_task_layer2: without rescue, the execution will return a non-zero  return code in shell and also report the error
    with rescue, the program will return 0
     ]
    ---Step1: [step1: step 1 ]
    self: final context exec vars:
    
    (*core.Cache)({
      "up_runtime_task_layer_number": 2,
      "loopitem": "item2",
      "loopindex": 1,
      "loopindex1": 2,
      "last_result": (*utils.ExecResult)({
        Cmd: "echo \"close the file .....\"",
        Code: 0,
        Output: "close the file .....",
        ErrMsg: ""
      })
    })
    
    cmd( 1):
    echo """opening file: {{.loopitem}}"""
    
    -
    opening file: item2
    
    -
     .. ok
    cmd( 2):
    echo "hello"|grep "world"
    
    -
    
    -
     .. failed(suppressed if it is not the last step)
     WARN: [ignoreError:] - [Error ignored!!!]
    ---Step2: [
    step2in this case, since there is no ignoreError, the exception was captured by task level finaly code block
    opened file is safely closed
    to make the flow to continue to reach step2, use ignoreError
    ]
    self: final context exec vars:
    
    (*core.Cache)({
      "up_runtime_task_layer_number": 2,
      "loopitem": "item2",
      "loopindex": 1,
      "loopindex1": 2,
      "last_result": (*utils.ExecResult)({
        Cmd: "echo \"hello\"|grep \"world\"",
        Code: 1,
        Output: "",
        ErrMsg: "exit status 1"
      })
    })
    
    ~~~SubStep1: [print:  ]
    step 2
    task Finally:
    --Step1: [
    close_fileensure the opened file is closed
    ]
    self: final context exec vars:
    
    (*core.Cache)({
      "loopindex1": 2,
      "up_runtime_task_layer_number": 2,
      "loopitem": "item2",
      "loopindex": 1
    })
    
    cmd( 1):
    echo "close the file ....."
    
    -
    close the file .....
    
    -
     .. ok
    . ok
    
```


##### Logs with different verbose level
* [c0184 log - verbose level v](../../logs/c0184_v)
* [c0184 log - verbose level vv](../../logs/c0184_vv)
* [c0184 log - verbose level vvv](../../logs/c0184_vvvv)
* [c0184 log - verbose level vvvv](../../logs/c0184_vvvv)
* [c0184 log - verbose level vvvvv](../../logs/c0184_vvvvv)

##### Raw logs with different verbose level
* [c0184 raw log - verbose level v](../../reflogs/c0184_v.log)
* [c0184 raw log - verbose level vv](../../reflogs/c0184_vv.log)
* [c0184 raw log - verbose level vvv](../../reflogs/c0184_vvv.log)
* [c0184 raw log - verbose level vvvv](../../reflogs/c0184_vvvv.log)
* [c0184 raw log - verbose level vvvvv](../../reflogs/c0184_vvvvv.log)








### Other references:
* [shell func:](../../quick-start/c0002/)
* [error handling:](../../test-debug/error_handling/)
* [finally and rescue:](../../flow-controll/c0174/)
* [finally and rescue:](../../flow-controll/c0183/)
